Workbook

Sheet Prosedur
A2: Tabel fakta | B2: data numerik | C2: ide yang digunakan id unik
C3: copas data numerik saja
A5: Dimensi | B5: data kategorikal | C5: copas value 1 kolom
C6: hapus duplikat
C7: buat ide unik sesuai kategorinya
B8: tanggal | C8: copas value 1 kolom
C9: pisahkan berdasarkan tahun, bulan, dan hari | D9: =YEAR(B2)
D10: =MONTH(B2)
D11: =DAY(B2)

Sheet Data Mentah
A1: id_reservasi | B1: tanggal_checkin | C1: tanggal_checkout | D1: timestamp | E1: id_tamu | F1: nama_tamu | G1: tipe_kamar | H1: jumlah_malam | I1: harga_per_malam | J1: total_biaya | K1: metode_pembayaran | L1: status_reservasi | M1: kota_hotel
A2: RES000001 | B2: 45028 | C2: 45036 | D2: 45028.774 | E2: CUS002594 | F2: Irsad Maheswara, S.Farm | G2: SUITE | H2: 8 | I2: 1186000 | J2: 9488000 | K2: Tunai | L2: SELESAI | M2: Makassar
A3: RES000002 | B3: 45239 | C3: 45246 | D3: 45239.785 | E3: CUS001748 | F3: Puspa Hutasoit | G3: Deluxe | H3: 7 | I3: 632000 | J3: 4424000 | K3: E-Wallet | L3: SELESAI | M3: Medan
A4: RES000003 | B4: 45413 | C4: 45417 | D4: 45413.438 | E4: CUS000497 | F4: Humaira Adriansyah | G4: suite | H4: 4 | I4: 1293000 | J4: 5172000 | K4: Kartu Debit | L4: terkonfirmasi | M4: Medan
A5: RES000004 | B5: 45047 | C5: 45049 | D5: 45047.46 | E5: CUS001710 | F5: Patricia Mangunsong | G5: standard | H5: 2 | I5: 318000 | J5: 636000 | K5: Kartu Kredit | L5: Selesai | M5: Manado
A6: RES000005 | B6: 44606 | C6: 44613 | D6: 44606.221 | E6: CUS001953 | F6: Olivia Putra | G6: suite | H6: 7 | I6: 1095000 | J6: 7665000 | K6: Tunai | L6: Terkonfirmasi | M6: Bekasi
A7: RES000006 | B7: 44900 | C7: 44902 | D7: 44900.478 | E7: CUS002257 | F7: Balijan Irawan, M.M. | G7: Superior | H7: 2 | I7: 448000 | J7: 896000 | L7: Terkonfirmasi | M7: Batam
A8: RES000007 | B8: 44850 | C8: 44859 | D8: 44850.113 | E8: CUS000342 | F8: Irnanto Prabowo | G8: Deluxe | H8: 9 | I8: 614000 | J8: 5526000 | K8: QRIS | L8: Selesai | M8: Bekasi
A9: RES000008 | B9: 44758 | C9: 44767 | D9: 44758.791 | E9: CUS001244 | F9: Embuh Jailani | G9: Deluxe | H9: 9 | I9: 582000 | J9: 5238000 | K9: Kartu Kredit | L9: Terkonfirmasi | M9: Bekasi
A10: RES000009 | B10: 44599 | C10: 44605 | D10: 44599.497 | E10: CUS001107 | F10: Hj. Ayu Gunarto | G10: Deluxe | H10: 6 | I10: 657000 | J10: 3942000 | K10: Kartu Debit | L10: Terkonfirmasi | M10: Bandung
A11: RES000010 | B11: 45473 | C11: 45482 | D11: 45473.64 | E11: CUS000007 | F11: Puput Yulianti | G11: Suite | H11: 9 | I11: 1251000 | J11: 11259000 | K11: Kartu Kredit | L11: terkonfirmasi | M11: Bandung
A12: RES000011 | B12: 44737 | C12: 44743 | D12: 44737.923 | E12: CUS001669 | F12: Jamalia Maheswara | G12: Deluxe | H12: 6 | I12: 663000 | J12: 3978000 | K12: Tunai | L12: Selesai | M12: Jakarta
A13: RES000012 | B13: 45317 | C13: 45323 | D13: 45317.441 | E13: CUS002190 | F13: Dr. Qori Prayoga, M.Kom. | G13: Deluxe | H13: 6 | I13: 567000 | J13: 3402000 | K13: Transfer Bank | L13: Menunggu | M13: Balikpapan
A14: RES000013 | B14: 45337 | C14: 45342 | D14: 45337.421 | E14: CUS000636 | F14: KH. Viktor Hasanah, S.Kom | G14: standard | H14: 5 | I14: 333000 | J14: 1665000 | K14: Kartu Kredit | L14: selesai | M14: Bandung
A15: RES000014 | B15: 45156 | C15: 45158 | D15: 45156.782 | E15: CUS001575 | F15: Ella Uwais | G15: Standard | H15: 2 | I15: 355000 | J15: 710000 | K15: Kartu Debit | L15: selesai | M15: Semarang
A16: RES000015 | B16: 44693 | C16: 44697 | D16: 44693.052 | E16: CUS002059 | F16: Hj. Yulia Kusmawati, S.E.I | G16: Superior | H16: 4 | I16: 487000 | J16: 1948000 | K16: Tunai | L16: TERKONFIRMASI | M16: Medan
A17: RES000016 | B17: 45161 | C17: 45167 | D17: 45161.209 | E17: CUS003000 | F17: Chelsea Hassanah | G17: DELUXE | H17: 6 | I17: 576000 | J17: 3456000 | K17: Transfer Bank | L17: dibatalkan | M17: Yogyakarta
A18: RES000017 | B18: 45083 | C18: 45092 | D18: 45083.782 | E18: CUS000844 | F18: drg. Cinthia Oktaviani, S.Ked | G18: Superior | H18: 9 | I18: 415000 | J18: 3735000 | K18: Kartu Debit | L18: Selesai | M18: Jakarta
A19: RES000018 | B19: 44929 | C19: 44930 | D19: 44929.768 | E19: CUS002807 | F19: Tgk. Putri Halim | G19: Superior | H19: 1 | I19: 441000 | J19: 441000 | K19: Kartu Debit | L19: SELESAI | M19: Solo
... A22: RES000021 | B22: 45317 | C22: 45322 | D22: 45317.655 | E22: CUS001904 | F22: Tina Uwais | G22: SUITE | H22: 5 | I22: 1214000 | J22: 6070000 | K22: Transfer Bank | L22: terkonfirmasi | M22: Makassar
A23: RES000022 | B23: 45629 | C23: 45633 | D23: 45629.753 | E23: CUS000829 | F23: Puspa Widodo, S.E.I | G23: Superior | I23: 425000 | J23: 1700000 | K23: Kartu Kredit | L23: Terkonfirmasi | M23: Samarinda
A24: RES000023 | B24: 45101 | C24: 45106 | D24: 45101.184 | E24: CUS001803 | F24: R.M. Dagel Waskita, S.Pt | G24: suite | H24: 5 | I24: 1217000 | J24: 6085000 | K24: Tunai | L24: Selesai | M24: Yogyakarta
A25: RES000024 | B25: 44826 | C25: 44827 | D25: 44826.082 | E25: CUS000875 | F25: dr. Agnes Prayoga | G25: Superior | H25: 1 | I25: 449000 | J25: 449000 | K25: Kartu Debit | L25: Menunggu | M25: Manado
A26: RES000025 | B26: 45580 | C26: 45581 | D26: 45580.264 | E26: CUS000386 | F26: Kayla Maryati | G26: superior | H26: 1 | I26: 507000 | J26: 507000 | K26: Tunai | L26: Terkonfirmasi | M26: Bogor
A27: RES000026 | B27: 45308 | C27: 45316 | D27: 45308.295 | E27: CUS001100 | F27: Jindra Halimah | G27: Deluxe | H27: 8 | I27: 575000 | J27: 4600000 | K27: Kartu Kredit | L27: Terkonfirmasi | M27: Surabaya
A28: RES000027 | B28: 45331 | C28: 45339 | D28: 45331.58 | E28: CUS000424 | F28: Sutan Pranata Aryani, S.Farm | G28: Standard | H28: 8 | I28: 398000 | J28: 3184000 | K28: Tunai | L28: Terkonfirmasi | M28: Bogor
A29: RES000028 | B29: 45467 | C29: 45472 | D29: 45467.362 | E29: CUS002439 | F29: Prabu Mayasari | G29: SUITE | H29: 5 | I29: 1091000 | J29: 5455000 | L29: Selesai | M29: Makassar
A30: RES000029 | B30: 44755 | C30: 44758 | D30: 44755.759 | E30: CUS002688 | F30: Drs. Kasim Kurniawan, S.H. | G30: Deluxe | H30: 3 | I30: 616000 | J30: 1848000 | K30: QRIS | L30: Menunggu | M30: Denpasar
A31: RES000030 | B31: 44944 | C31: 44953 | D31: 44944.309 | E31: CUS000090 | F31: Oskar Kuswandari | G31: STANDARD | I31: 331000 | J31: 2979000 | K31: Transfer Bank | L31: Terkonfirmasi | M31: Balikpapan
A32: RES000031 | B32: 45349 | C32: 45357 | D32: 45349.86 | E32: CUS000164 | F32: Mahesa Widodo | G32: Deluxe | H32: 8 | I32: 639000 | J32: 5112000 | L32: Terkonfirmasi | M32: Surabaya
A33: RES000032 | B33: 45585 | C33: 45594 | D33: 45585.865 | E33: CUS001152 | F33: H. Harjo Santoso | G33: STANDARD | H33: 9 | I33: 383000 | J33: 3447000 | K33: E-Wallet | L33: TERKONFIRMASI | M33: Balikpapan
A34: RES000033 | B34: 45202 | C34: 45205 | D34: 45202.11 | E34: CUS002217 | F34: Atma Palastri | G34: DELUXE | H34: 3 | I34: 634000 | J34: 1902000 | K34: Tunai | L34: MENUNGGU | M34: Padang
A35: RES000034 | B35: 44845 | C35: 44849 | D35: 44845.156 | E35: CUS002666 | F35: Heryanto Adriansyah | G35: STANDARD | H35: 4 | I35: 337000 | J35: 1348000 | K35: Tunai | L35: terkonfirmasi | M35: Manado
A36: RES000035 | B36: 45569 | C36: 45571 | D36: 45569.059 | E36: CUS001198 | F36: Heru Hidayanto | G36: standard | H36: 2 | I36: 371000 | J36: 742000 | K36: Transfer Bank | L36: MENUNGGU | M36: Makassar
A37: RES000036 | B37: 45633 | C37: 45640 | D37: 45633.987 | E37: CUS001311 | F37: Zelaya Sitompul, M.Kom. | G37: Suite | H37: 7 | I37: 1297000 | J37: 9079000 | K37: QRIS | L37: SELESAI | M37: Bogor
A38: RES000037 | B38: 45151 | C38: 45159 | D38: 45151.899 | E38: CUS000506 | F38: Kalim Saefullah | G38: suite | H38: 8 | I38: 1340000 | J38: 10720000 | L38: terkonfirmasi | M38: Solo
A39: RES000038 | B39: 45302 | C39: 45311 | D39: 45302.873 | E39: CUS002964 | F39: Uchita Haryanti, M.Pd | G39: Standard | I39: 369000 | J39: 3321000 | K39: E-Wallet | L39: Terkonfirmasi | M39: Batam
A40: RES000039 | B40: 45643 | C40: 45650 | D40: 45643.446 | E40: CUS002912 | F40: Ir. Cahya Widiastuti | G40: suite | H40: 7 | I40: 1357000 | J40: 9499000 | L40: Selesai | M40: Samarinda
A41: RES000040 | B41: 44768 | C41: 44777 | D41: 44768.859 | E41: CUS002019 | F41: Aslijan Damanik | G41: Deluxe | H41: 9 | I41: 670000 | J41: 6030000 | K41: Tunai | L41: Selesai | M41: Bekasi
A42: RES000041 | B42: 44936 | C42: 44939 | D42: 44936.664 | E42: CUS002323 | F42: Tgk. Ina Anggriawan, M.Pd | G42: suite | H42: 3 | I42: 1339000 | J42: 4017000 | K42: QRIS | L42: Selesai | M42: Semarang
...

Sheet Master Data
A1: id_reservasi | B1: id_checkin | C1: tanggal_checkin | D1: id_checkout | E1: tanggal_checkout | F1: timestamp | G1: id_tamu | H1: nama_tamu | I1: id_kamar | J1: tipe_kamar | K1: jumlah_malam | L1: harga_per_malam | M1: total_biaya | N1: id_pembayaran | O1: metode_pembayaran | P1: id_status_reservasi | Q1: status_reservasi | R1: id_kota_hotel | S1: kota_hotel
A2: RES000001 | B2: =_xlfn.XLOOKUP(Table2[[#This Row],[tanggal_checkin]],Table6[tanggal_checkin],Table6[id_checkin]) -> CI 0459 | C2: 2023-04-12 | D2: =_xlfn.XLOOKUP(Table2[[#This Row],[tanggal_checkout]],Table4[tanggal_checkout],Table4[id_checkout]) -> CO 0001 | E2: 2023-04-20 | F2: 0.77447917 | G2: =_xlfn.XLOOKUP(Table2[[#This Row],[nama_tamu]],Table10[nama_tamu],Table10[id_tamu]) -> CUS 1939 | H2: Irsad Maheswara, S.Farm | I2: =_xlfn.XLOOKUP(Table2[[#This Row],[tipe_kamar]],Table12[tipe_kamar],Table12[id_kamar]) -> KMR 003 | J2: Suite | K2: 8 | L2: 1186000 | M2: 9488000 | N2: =_xlfn.XLOOKUP(Table2[[#This Row],[metode_pembayaran]],Table11[metode_pembayaran],Table11[id_pembayaran]) -> MP 06 | O2: Tunai | P2: =_xlfn.XLOOKUP(Table2[[#This Row],[status_reservasi]],'Dim Status Reservasi'!$B$2:$B$5,'Dim Status Reservasi'!$A$2:$A$5) -> ST 003 | Q2: Selesai | R2: =_xlfn.XLOOKUP(Table2[[#This Row],[kota_hotel]],'Dim Kota Hotel'!$B$2:$B$21,'Dim Kota Hotel'!$A$2:$A$21) -> LOK 009 | S2: Makassar
A3: RES000002 | B3: =_xlfn.XLOOKUP(Table2[[#This Row],[tanggal_checkin]],Table6[tanggal_checkin],Table6[id_checkin]) -> CI 0667 | C3: 2023-11-09 | D3: =_xlfn.XLOOKUP(Table2[[#This Row],[tanggal_checkout]],Table4[tanggal_checkout],Table4[id_checkout]) -> CO 0674 | E3: 2023-11-16 | F3: 0.78450231 | G3: =_xlfn.XLOOKUP(Table2[[#This Row],[nama_tamu]],Table10[nama_tamu],Table10[id_tamu]) -> CUS 2945 | H3: Puspa Hutasoit | I3: =_xlfn.XLOOKUP(Table2[[#This Row],[tipe_kamar]],Table12[tipe_kamar],Table12[id_kamar]) -> KMR 001 | J3: Deluxe | K3: 7 | L3: 632000 | M3: 4424000 | N3: =_xlfn.XLOOKUP(Table2[[#This Row],[metode_pembayaran]],Table11[metode_pembayaran],Table11[id_pembayaran]) -> MP 01 | O3: E-Wallet | P3: =_xlfn.XLOOKUP(Table2[[#This Row],[status_reservasi]],'Dim Status Reservasi'!$B$2:$B$5,'Dim Status Reservasi'!$A$2:$A$5) -> ST 003 | Q3: Selesai | R3: =_xlfn.XLOOKUP(Table2[[#This Row],[kota_hotel]],'Dim Kota Hotel'!$B$2:$B$21,'Dim Kota Hotel'!$A$2:$A$21) -> LOK 012 | S3: Medan
A4: RES000003 | B4: =_xlfn.XLOOKUP(Table2[[#This Row],[tanggal_checkin]],Table6[tanggal_checkin],Table6[id_checkin]) -> CI 0836 | C4: 2024-05-01 | D4: =_xlfn.XLOOKUP(Table2[[#This Row],[tanggal_checkout]],Table4[tanggal_checkout],Table4[id_checkout]) -> CO 0843 | E4: 2024-05-05 | F4: 0.43837963 | G4: =_xlfn.XLOOKUP(Table2[[#This Row],[nama_tamu]],Table10[nama_tamu],Table10[id_tamu]) -> CUS 1726 | H4: Humaira Adriansyah | I4: =_xlfn.XLOOKUP(Table2[[#This Row],[tipe_kamar]],Table12[tipe_kamar],Table12[id_kamar]) -> KMR 003 | J4: Suite | K4: 4 | L4: 1293000 | M4: 5172000 | N4: =_xlfn.XLOOKUP(Table2[[#This Row],[metode_pembayaran]],Table11[metode_pembayaran],Table11[id_pembayaran]) -> MP 02 | O4: Kartu Debit | P4: =_xlfn.XLOOKUP(Table2[[#This Row],[status_reservasi]],'Dim Status Reservasi'!$B$2:$B$5,'Dim Status Reservasi'!$A$2:$A$5) -> ST 004 | Q4: Terkonfirmasi | R4: =_xlfn.XLOOKUP(Table2[[#This Row],[kota_hotel]],'Dim Kota Hotel'!$B$2:$B$21,'Dim Kota Hotel'!$A$2:$A$21) -> LOK 012 | S4: Medan
A5: RES000004 | B5: =_xlfn.XLOOKUP(Table2[[#This Row],[tanggal_checkin]],Table6[tanggal_checkin],Table6[id_checkin]) -> CI 0477 | C5: 2023-05-01 | D5: =_xlfn.XLOOKUP(Table2[[#This Row],[tanggal_checkout]],Table4[tanggal_checkout],Table4[id_checkout]) -> CO 0481 | E5: 2023-05-03 | F5: 0.46010417 | G5: =_xlfn.XLOOKUP(Table2[[#This Row],[nama_tamu]],Table10[nama_tamu],Table10[id_tamu]) -> CUS 2841 | H5: Patricia Mangunsong | I5: =_xlfn.XLOOKUP(Table2[[#This Row],[tipe_kamar]],Table12[tipe_kamar],Table12[id_kamar]) -> KMR 002 | J5: Standard | K5: 2 | L5: 318000 | M5: 636000 | N5: =_xlfn.XLOOKUP(Table2[[#This Row],[metode_pembayaran]],Table11[metode_pembayaran],Table11[id_pembayaran]) -> MP 03 | O5: Kartu Kredit | P5: =_xlfn.XLOOKUP(Table2[[#This Row],[status_reservasi]],'Dim Status Reservasi'!$B$2:$B$5,'Dim Status Reservasi'!$A$2:$A$5) -> ST 003 | Q5: Selesai | R5: =_xlfn.XLOOKUP(Table2[[#This Row],[kota_hotel]],'Dim Kota Hotel'!$B$2:$B$21,'Dim Kota Hotel'!$A$2:$A$21) -> LOK 011 | S5: Manado
A6: RES000005 | B6: =_xlfn.XLOOKUP(Table2[[#This Row],[tanggal_checkin]],Table6[tanggal_checkin],Table6[id_checkin]) -> CI 0044 | C6: 2022-02-14 | D6: =_xlfn.XLOOKUP(Table2[[#This Row],[tanggal_checkout]],Table4[tanggal_checkout],Table4[id_checkout]) -> CO 0051 | E6: 2022-02-21 | F6: 0.22133102 | G6: =_xlfn.XLOOKUP(Table2[[#This Row],[nama_tamu]],Table10[nama_tamu],Table10[id_tamu]) -> CUS 2767 | H6: Olivia Putra | I6: =_xlfn.XLOOKUP(Table2[[#This Row],[tipe_kamar]],Table12[tipe_kamar],Table12[id_kamar]) -> KMR 003 | J6: Suite | K6: 7 | L6: 1095000 | M6: 7665000 | N6: =_xlfn.XLOOKUP(Table2[[#This Row],[metode_pembayaran]],Table11[metode_pembayaran],Table11[id_pembayaran]) -> MP 06 | O6: Tunai | P6: =_xlfn.XLOOKUP(Table2[[#This Row],[status_reservasi]],'Dim Status Reservasi'!$B$2:$B$5,'Dim Status Reservasi'!$A$2:$A$5) -> ST 004 | Q6: Terkonfirmasi | R6: =_xlfn.XLOOKUP(Table2[[#This Row],[kota_hotel]],'Dim Kota Hotel'!$B$2:$B$21,'Dim Kota Hotel'!$A$2:$A$21) -> LOK 005 | S6: Bekasi
A7: RES000006 | B7: =_xlfn.XLOOKUP(Table2[[#This Row],[tanggal_checkin]],Table6[tanggal_checkin],Table6[id_checkin]) -> CI 0335 | C7: 2022-12-05 | D7: =_xlfn.XLOOKUP(Table2[[#This Row],[tanggal_checkout]],Table4[tanggal_checkout],Table4[id_checkout]) -> CO 0336 | E7: 2022-12-07 | F7: 0.47791667 | G7: =_xlfn.XLOOKUP(Table2[[#This Row],[nama_tamu]],Table10[nama_tamu],Table10[id_tamu]) -> CUS 0295 | H7: Balijan Irawan, M.M. | I7: =_xlfn.XLOOKUP(Table2[[#This Row],[tipe_kamar]],Table12[tipe_kamar],Table12[id_kamar]) -> KMR 004 | J7: Superior | K7: 2 | L7: 448000 | M7: 896000 | N7: =_xlfn.XLOOKUP(Table2[[#This Row],[metode_pembayaran]],Table11[metode_pembayaran],Table11[id_pembayaran]) -> MP 06 | O7: Tunai | P7: =_xlfn.XLOOKUP(Table2[[#This Row],[status_reservasi]],'Dim Status Reservasi'!$B$2:$B$5,'Dim Status Reservasi'!$A$2:$A$5) -> ST 004 | Q7: Terkonfirmasi | R7: =_xlfn.XLOOKUP(Table2[[#This Row],[kota_hotel]],'Dim Kota Hotel'!$B$2:$B$21,'Dim Kota Hotel'!$A$2:$A$21) -> LOK 004 | S7: Batam
A8: RES000007 | B8: =_xlfn.XLOOKUP(Table2[[#This Row],[tanggal_checkin]],Table6[tanggal_checkin],Table6[id_checkin]) -> CI 0286 | C8: 2022-10-16 | D8: =_xlfn.XLOOKUP(Table2[[#This Row],[tanggal_checkout]],Table4[tanggal_checkout],Table4[id_checkout]) -> CO 0293 | E8: 2022-10-25 | F8: 0.11313657 | G8: =_xlfn.XLOOKUP(Table2[[#This Row],[nama_tamu]],Table10[nama_tamu],Table10[id_tamu]) -> CUS 1934 | H8: Irnanto Prabowo | I8: =_xlfn.XLOOKUP(Table2[[#This Row],[tipe_kamar]],Table12[tipe_kamar],Table12[id_kamar]) -> KMR 001 | J8: Deluxe | K8: 9 | L8: 614000 | M8: 5526000 | N8: =_xlfn.XLOOKUP(Table2[[#This Row],[metode_pembayaran]],Table11[metode_pembayaran],Table11[id_pembayaran]) -> MP 04 | O8: QRIS | P8: =_xlfn.XLOOKUP(Table2[[#This Row],[status_reservasi]],'Dim Status Reservasi'!$B$2:$B$5,'Dim Status Reservasi'!$A$2:$A$5) -> ST 003 | Q8: Selesai | R8: =_xlfn.XLOOKUP(Table2[[#This Row],[kota_hotel]],'Dim Kota Hotel'!$B$2:$B$21,'Dim Kota Hotel'!$A$2:$A$21) -> LOK 005 | S8: Bekasi
A9: RES000008 | B9: =_xlfn.XLOOKUP(Table2[[#This Row],[tanggal_checkin]],Table6[tanggal_checkin],Table6[id_checkin]) -> CI 0194 | C9: 2022-07-16 | D9: =_xlfn.XLOOKUP(Table2[[#This Row],[tanggal_checkout]],Table4[tanggal_checkout],Table4[id_checkout]) -> CO 0204 | E9: 2022-07-25 | F9: 0.79085648 | G9: =_xlfn.XLOOKUP(Table2[[#This Row],[nama_tamu]],Table10[nama_tamu],Table10[id_tamu]) -> CUS 1262 | H9: Embuh Jailani | I9: =_xlfn.XLOOKUP(Table2[[#This Row],[tipe_kamar]],Table12[tipe_kamar],Table12[id_kamar]) -> KMR 001 | J9: Deluxe | K9: 9 | L9: 582000 | M9: 5238000 | N9: =_xlfn.XLOOKUP(Table2[[#This Row],[metode_pembayaran]],Table11[metode_pembayaran],Table11[id_pembayaran]) -> MP 03 | O9: Kartu Kredit | P9: =_xlfn.XLOOKUP(Table2[[#This Row],[status_reservasi]],'Dim Status Reservasi'!$B$2:$B$5,'Dim Status Reservasi'!$A$2:$A$5) -> ST 004 | Q9: Terkonfirmasi | R9: =_xlfn.XLOOKUP(Table2[[#This Row],[kota_hotel]],'Dim Kota Hotel'!$B$2:$B$21,'Dim Kota Hotel'!$A$2:$A$21) -> LOK 005 | S9: Bekasi
A10: RES000009 | B10: =_xlfn.XLOOKUP(Table2[[#This Row],[tanggal_checkin]],Table6[tanggal_checkin],Table6[id_checkin]) -> CI 0037 | C10: 2022-02-07 | D10: =_xlfn.XLOOKUP(Table2[[#This Row],[tanggal_checkout]],Table4[tanggal_checkout],Table4[id_checkout]) -> CO 0043 | E10: 2022-02-13 | F10: 0.49701389 | G10: =_xlfn.XLOOKUP(Table2[[#This Row],[nama_tamu]],Table10[nama_tamu],Table10[id_tamu]) -> CUS 1681 | H10: Hj. Ayu Gunarto | I10: =_xlfn.XLOOKUP(Table2[[#This Row],[tipe_kamar]],Table12[tipe_kamar],Table12[id_kamar]) -> KMR 001 | J10: Deluxe | K10: 6 | L10: 657000 | M10: 3942000 | N10: =_xlfn.XLOOKUP(Table2[[#This Row],[metode_pembayaran]],Table11[metode_pembayaran],Table11[id_pembayaran]) -> MP 02 | O10: Kartu Debit | P10: =_xlfn.XLOOKUP(Table2[[#This Row],[status_reservasi]],'Dim Status Reservasi'!$B$2:$B$5,'Dim Status Reservasi'!$A$2:$A$5) -> ST 004 | Q10: Terkonfirmasi | R10: =_xlfn.XLOOKUP(Table2[[#This Row],[kota_hotel]],'Dim Kota Hotel'!$B$2:$B$21,'Dim Kota Hotel'!$A$2:$A$21) -> LOK 002 | S10: Bandung
A11: RES000010 | B11: =_xlfn.XLOOKUP(Table2[[#This Row],[tanggal_checkin]],Table6[tanggal_checkin],Table6[id_checkin]) -> CI 0896 | C11: 2024-06-30 | D11: =_xlfn.XLOOKUP(Table2[[#This Row],[tanggal_checkout]],Table4[tanggal_checkout],Table4[id_checkout]) -> CO 0906 | E11: 2024-07-09 | F11: 0.64009259 | G11: =_xlfn.XLOOKUP(Table2[[#This Row],[nama_tamu]],Table10[nama_tamu],Table10[id_tamu]) -> CUS 2936 | H11: Puput Yulianti | I11: =_xlfn.XLOOKUP(Table2[[#This Row],[tipe_kamar]],Table12[tipe_kamar],Table12[id_kamar]) -> KMR 003 | J11: Suite | K11: 9 | L11: 1251000 | M11: 11259000 | N11: =_xlfn.XLOOKUP(Table2[[#This Row],[metode_pembayaran]],Table11[metode_pembayaran],Table11[id_pembayaran]) -> MP 03 | O11: Kartu Kredit | P11: =_xlfn.XLOOKUP(Table2[[#This Row],[status_reservasi]],'Dim Status Reservasi'!$B$2:$B$5,'Dim Status Reservasi'!$A$2:$A$5) -> ST 004 | Q11: Terkonfirmasi | R11: =_xlfn.XLOOKUP(Table2[[#This Row],[kota_hotel]],'Dim Kota Hotel'!$B$2:$B$21,'Dim Kota Hotel'!$A$2:$A$21) -> LOK 002 | S11: Bandung
A12: RES000011 | B12: =_xlfn.XLOOKUP(Table2[[#This Row],[tanggal_checkin]],Table6[tanggal_checkin],Table6[id_checkin]) -> CI 0173 | C12: 2022-06-25 | D12: =_xlfn.XLOOKUP(Table2[[#This Row],[tanggal_checkout]],Table4[tanggal_checkout],Table4[id_checkout]) -> CO 0181 | E12: 2022-07-01 | F12: 0.92284722 | G12: =_xlfn.XLOOKUP(Table2[[#This Row],[nama_tamu]],Table10[nama_tamu],Table10[id_tamu]) -> CUS 1980 | H12: Jamalia Maheswara | I12: =_xlfn.XLOOKUP(Table2[[#This Row],[tipe_kamar]],Table12[tipe_kamar],Table12[id_kamar]) -> KMR 001 | J12: Deluxe | K12: 6 | L12: 663000 | M12: 3978000 | N12: =_xlfn.XLOOKUP(Table2[[#This Row],[metode_pembayaran]],Table11[metode_pembayaran],Table11[id_pembayaran]) -> MP 06 | O12: Tunai | P12: =_xlfn.XLOOKUP(Table2[[#This Row],[status_reservasi]],'Dim Status Reservasi'!$B$2:$B$5,'Dim Status Reservasi'!$A$2:$A$5) -> ST 003 | Q12: Selesai | R12: =_xlfn.XLOOKUP(Table2[[#This Row],[kota_hotel]],'Dim Kota Hotel'!$B$2:$B$21,'Dim Kota Hotel'!$A$2:$A$21) -> LOK 008 | S12: Jakarta
A13: RES000012 | B13: =_xlfn.XLOOKUP(Table2[[#This Row],[tanggal_checkin]],Table6[tanggal_checkin],Table6[id_checkin]) -> CI 0742 | C13: 2024-01-26 | D13: =_xlfn.XLOOKUP(Table2[[#This Row],[tanggal_checkout]],Table4[tanggal_checkout],Table4[id_checkout]) -> CO 0751 | E13: 2024-02-01 | F13: 0.44092593 | G13: =_xlfn.XLOOKUP(Table2[[#This Row],[nama_tamu]],Table10[nama_tamu],Table10[id_tamu]) -> CUS 0836 | H13: Dr. Qori Prayoga, M.Kom. | I13: =_xlfn.XLOOKUP(Table2[[#This Row],[tipe_kamar]],Table12[tipe_kamar],Table12[id_kamar]) -> KMR 001 | J13: Deluxe | K13: 6 | L13: 567000 | M13: 3402000 | N13: =_xlfn.XLOOKUP(Table2[[#This Row],[metode_pembayaran]],Table11[metode_pembayaran],Table11[id_pembayaran]) -> MP 05 | O13: Transfer Bank | P13: =_xlfn.XLOOKUP(Table2[[#This Row],[status_reservasi]],'Dim Status Reservasi'!$B$2:$B$5,'Dim Status Reservasi'!$A$2:$A$5) -> ST 002 | Q13: Menunggu | R13: =_xlfn.XLOOKUP(Table2[[#This Row],[kota_hotel]],'Dim Kota Hotel'!$B$2:$B$21,'Dim Kota Hotel'!$A$2:$A$21) -> LOK 001 | S13: Balikpapan
... A4371: RES004455 | B4371: =_xlfn.XLOOKUP(Table2[[#This Row],[tanggal_checkin]],Table6[tanggal_checkin],Table6[id_checkin]) -> CI 0594 | C4371: 2023-08-27 | D4371: =_xlfn.XLOOKUP(Table2[[#This Row],[tanggal_checkout]],Table4[tanggal_checkout],Table4[id_checkout]) -> CO 0598 | E4371: 2023-08-31 | F4371: 0.49390046 | G4371: =_xlfn.XLOOKUP(Table2[[#This Row],[nama_tamu]],Table10[nama_tamu],Table10[id_tamu]) -> CUS 0343 | H4371: Cagak Zulaika | I4371: =_xlfn.XLOOKUP(Table2[[#This Row],[tipe_kamar]],Table12[tipe_kamar],Table12[id_kamar]) -> KMR 002 | J4371: Standard | K4371: 4 | L4371: 397000 | M4371: 1588000 | N4371: =_xlfn.XLOOKUP(Table2[[#This Row],[metode_pembayaran]],Table11[metode_pembayaran],Table11[id_pembayaran]) -> MP 02 | O4371: Kartu Debit | P4371: =_xlfn.XLOOKUP(Table2[[#This Row],[status_reservasi]],'Dim Status Reservasi'!$B$2:$B$5,'Dim Status Reservasi'!$A$2:$A$5) -> ST 004 | Q4371: Terkonfirmasi | R4371: =_xlfn.XLOOKUP(Table2[[#This Row],[kota_hotel]],'Dim Kota Hotel'!$B$2:$B$21,'Dim Kota Hotel'!$A$2:$A$21) -> LOK 017 | S4371: Semarang

Sheet Tabel Fakta
A1: id_reservasi | B1: timestamp | C1: jumlah_malam | D1: harga_per_malam | E1: total_biaya | F1: id_tamu | G1: id_kamar | H1: id_pembayaran | I1: id_status_reservasi | J1: id_kota_hotel | K1: id_checkin | L1: id_checkout
A2: RES000001 | B2: 0.77447917 | C2: 8 | D2: 1186000 | E2: 9488000 | F2: CUS 1939 | G2: KMR 003 | H2: MP 06 | I2: ST 003 | J2: LOK 009 | K2: CI 0459 | L2: CO 0001
A3: RES000002 | B3: 0.78450231 | C3: 7 | D3: 632000 | E3: 4424000 | F3: CUS 2945 | G3: KMR 001 | H3: MP 01 | I3: ST 003 | J3: LOK 012 | K3: CI 0667 | L3: CO 0674
A4: RES000003 | B4: 0.43837963 | C4: 4 | D4: 1293000 | E4: 5172000 | F4: CUS 1726 | G4: KMR 003 | H4: MP 02 | I4: ST 004 | J4: LOK 012 | K4: CI 0836 | L4: CO 0843
A5: RES000004 | B5: 0.46010417 | C5: 2 | D5: 318000 | E5: 636000 | F5: CUS 2841 | G5: KMR 002 | H5: MP 03 | I5: ST 003 | J5: LOK 011 | K5: CI 0477 | L5: CO 0481
A6: RES000005 | B6: 0.22133102 | C6: 7 | D6: 1095000 | E6: 7665000 | F6: CUS 2767 | G6: KMR 003 | H6: MP 06 | I6: ST 004 | J6: LOK 005 | K6: CI 0044 | L6: CO 0051
A7: RES000006 | B7: 0.47791667 | C7: 2 | D7: 448000 | E7: 896000 | F7: CUS 0295 | G7: KMR 004 | H7: MP 06 | I7: ST 004 | J7: LOK 004 | K7: CI 0335 | L7: CO 0336
A8: RES000007 | B8: 0.11313657 | C8: 9 | D8: 614000 | E8: 5526000 | F8: CUS 1934 | G8: KMR 001 | H8: MP 04 | I8: ST 003 | J8: LOK 005 | K8: CI 0286 | L8: CO 0293
A9: RES000008 | B9: 0.79085648 | C9: 9 | D9: 582000 | E9: 5238000 | F9: CUS 1262 | G9: KMR 001 | H9: MP 03 | I9: ST 004 | J9: LOK 005 | K9: CI 0194 | L9: CO 0204
A10: RES000009 | B10: 0.49701389 | C10: 6 | D10: 657000 | E10: 3942000 | F10: CUS 1681 | G10: KMR 001 | H10: MP 02 | I10: ST 004 | J10: LOK 002 | K10: CI 0037 | L10: CO 0043
A11: RES000010 | B11: 0.64009259 | C11: 9 | D11: 1251000 | E11: 11259000 | F11: CUS 2936 | G11: KMR 003 | H11: MP 03 | I11: ST 004 | J11: LOK 002 | K11: CI 0896 | L11: CO 0906
A12: RES000011 | B12: 0.92284722 | C12: 6 | D12: 663000 | E12: 3978000 | F12: CUS 1980 | G12: KMR 001 | H12: MP 06 | I12: ST 003 | J12: LOK 008 | K12: CI 0173 | L12: CO 0181
A13: RES000012 | B13: 0.44092593 | C13: 6 | D13: 567000 | E13: 3402000 | F13: CUS 0836 | G13: KMR 001 | H13: MP 05 | I13: ST 002 | J13: LOK 001 | K13: CI 0742 | L13: CO 0751
... A4371: RES004455 | B4371: 0.49390046 | C4371: 4 | D4371: 397000 | E4371: 1588000 | F4371: CUS 0343 | G4371: KMR 002 | H4371: MP 02 | I4371: ST 004 | J4371: LOK 017 | K4371: CI 0594 | L4371: CO 0598

Sheet Dim Tamu
A1: id_tamu | B1: nama_tamu
A2: CUS 0001 | B2: Abyasa Najmudin
A3: CUS 0002 | B3: Abyasa Rahmawati
A4: CUS 0003 | B4: Abyasa Zulaika
A5: CUS 0004 | B5: Ade Dongoran
A6: CUS 0005 | B6: Ade Farida
A7: CUS 0006 | B7: Ade Hutapea
A8: CUS 0007 | B8: Ade Nasyidah, S.Kom
A9: CUS 0008 | B9: Ade Prabowo
A10: CUS 0009 | B10: Ade Prayoga, S.E.
A11: CUS 0010 | B11: Ade Siregar
A12: CUS 0011 | B12: Ade Waluyo
... A4186: CUS 4185 | B4186: Zulfa Wahyudin

Sheet Dim Tipe Kamar
A1: id_kamar | B1: tipe_kamar
A2: KMR 001 | B2: Deluxe
A3: KMR 002 | B3: Standard
A4: KMR 003 | B4: Suite
A5: KMR 004 | B5: Superior

Sheet Dim Metode Pembayaran
A1: id_pembayaran | B1: metode_pembayaran
A2: MP 01 | B2: E-Wallet
A3: MP 02 | B3: Kartu Debit
A4: MP 03 | B4: Kartu Kredit
A5: MP 04 | B5: QRIS
A6: MP 05 | B6: Transfer Bank
A7: MP 06 | B7: Tunai

Sheet Dim Status Reservasi
A1: id_status_reservasi | B1: status_reservasi
A2: ST 001 | B2: Dibatalkan
A3: ST 002 | B3: Menunggu
A4: ST 003 | B4: Selesai
A5: ST 004 | B5: Terkonfirmasi

Sheet Dim Kota Hotel
A1: id_kota_hotel | B1: kota_hotel
A2: LOK 001 | B2: Balikpapan
A3: LOK 002 | B3: Bandung
A4: LOK 003 | B4: Banjarmasin
A5: LOK 004 | B5: Batam
A6: LOK 005 | B6: Bekasi
A7: LOK 006 | B7: Bogor
A8: LOK 007 | B8: Denpasar
A9: LOK 008 | B9: Jakarta
A10: LOK 009 | B10: Makassar
A11: LOK 010 | B11: Malang
A12: LOK 011 | B12: Manado
... A21: LOK 020 | B21: Yogyakarta

Sheet Dim Tanggal Check In
A1: id_checkin | B1: tanggal_checkin | C1: tahun | D1: bulan | E1: hari
A2: CI 0001 | B2: 2022-01-01 | C2: 2022 | D2: 1 | E2: 1
A3: CI 0002 | B3: 2022-01-02 | C3: 2022 | D3: 1 | E3: 2
A4: CI 0003 | B4: 2022-01-03 | C4: 2022 | D4: 1 | E4: 3
A5: CI 0004 | B5: 2022-01-04 | C5: 2022 | D5: 1 | E5: 4
A6: CI 0005 | B6: 2022-01-05 | C6: 2022 | D6: 1 | E6: 5
A7: CI 0006 | B7: 2022-01-06 | C7: 2022 | D7: 1 | E7: 6
A8: CI 0007 | B8: 2022-01-07 | C8: 2022 | D8: 1 | E8: 7
A9: CI 0008 | B9: 2022-01-08 | C9: 2022 | D9: 1 | E9: 8
A10: CI 0009 | B10: 2022-01-09 | C10: 2022 | D10: 1 | E10: 9
A11: CI 0010 | B11: 2022-01-10 | C11: 2022 | D11: 1 | E11: 10
A12: CI 0011 | B12: 2022-01-11 | C12: 2022 | D12: 1 | E12: 11
A13: CI 0012 | B13: 2022-01-12 | C13: 2022 | D13: 1 | E13: 12
... A1077: CI 1076 | B1077: 2024-12-30 | C1077: 2024 | D1077: 12 | E1077: 30

Sheet Dim Tanggal Check Out
A1: id_checkout | B1: tanggal_checkout | C1: tahun | D1: bulan | E1: hari
A2: CO 0001 | B2: 2023-04-20 | C2: 2023 | D2: 4 | E2: 20
A3: CO 0002 | B3: 2022-01-02 | C3: 2022 | D3: 1 | E3: 2
A4: CO 0003 | B4: 2022-01-03 | C4: 2022 | D4: 1 | E4: 3
A5: CO 0004 | B5: 2022-01-04 | C5: 2022 | D5: 1 | E5: 4
A6: CO 0005 | B6: 2022-01-05 | C6: 2022 | D6: 1 | E6: 5
A7: CO 0006 | B7: 2022-01-06 | C7: 2022 | D7: 1 | E7: 6
A8: CO 0007 | B8: 2022-01-07 | C8: 2022 | D8: 1 | E8: 7
A9: CO 0008 | B9: 2022-01-09 | C9: 2022 | D9: 1 | E9: 9
A10: CO 0009 | B10: 2022-01-10 | C10: 2022 | D10: 1 | E10: 10
A11: CO 0010 | B11: 2022-01-11 | C11: 2022 | D11: 1 | E11: 11
A12: CO 0011 | B12: 2022-01-12 | C12: 2022 | D12: 1 | E12: 12
A13: CO 0012 | B13: 2022-01-13 | C13: 2022 | D13: 1 | E13: 13
... A1086: CO 1085 | B1086: 2025-01-07 | C1086: 2025 | D1086: 1 | E1086: 7
